<?xml version="1.0"?>

<robot xmlns:xacro="http://www.ros.org/wiki/xacro">

    <!-- ============================= -->
    <!-- Robot Dimensions              -->
    <!-- ============================= -->

    <xacro:property name="wheel_radius" value="0.07"/>
    <xacro:property name="wheel_width" value="0.04"/>

    <!-- ============================= -->
    <!-- Left Wheel                    -->
    <!-- ============================= -->

    <link name="left_wheel">

        <visual>
            <origin xyz="0 0 0" rpy="1.5708 0 0"/>
            <geometry>
                <cylinder radius="${wheel_radius}"
                          length="${wheel_width}"/>
            </geometry>
            <material name="black"/>
        </visual>

        <collision>
            <origin xyz="0 0 0" rpy="1.5708 0 0"/>
            <geometry>
                <cylinder radius="${wheel_radius}"
                          length="${wheel_width}"/>
            </geometry>
        </collision>

        <inertial>
            <mass value="0.5"/>
            <origin xyz="0 0 0"/>
            <inertia
                ixx="0.001"
                ixy="0"
                ixz="0"
                iyy="0.001"
                iyz="0"
                izz="0.001"/>
        </inertial>

    </link>

    <joint name="left_wheel_joint" type="continuous">

        <parent link="base_link"/>
        <child link="left_wheel"/>

        <origin xyz="0 0.195 0.075"/>

        <axis xyz="0 1 0"/>

    </joint>

    <!-- ============================= -->
    <!-- Right Wheel                   -->
    <!-- ============================= -->

    <link name="right_wheel">

        <visual>
            <origin xyz="0 0 0" rpy="1.5708 0 0"/>
            <geometry>
                <cylinder radius="${wheel_radius}"
                          length="${wheel_width}"/>
            </geometry>
            <material name="black"/>
        </visual>

        <collision>
            <origin xyz="0 0 0" rpy="1.5708 0 0"/>
            <geometry>
                <cylinder radius="${wheel_radius}"
                          length="${wheel_width}"/>
            </geometry>
        </collision>

        <inertial>
            <mass value="0.5"/>
            <origin xyz="0 0 0"/>
            <inertia
                ixx="0.001"
                ixy="0"
                ixz="0"
                iyy="0.001"
                iyz="0"
                izz="0.001"/>
        </inertial>

    </link>

    <joint name="right_wheel_joint" type="continuous">

        <parent link="base_link"/>
        <child link="right_wheel"/>

        <origin xyz="0 -0.195 0.075"/>

        <axis xyz="0 1 0"/>

    </joint>

    <!-- ============================= -->
    <!-- Rear Caster Left              -->
    <!-- ============================= -->

    <link name="caster_wheel_left">
        <visual>
            <geometry>
                <sphere radius="0.05"/>   <!-- bigger radius — more stable -->
            </geometry>
            <material name="grey"/>
        </visual>
        <collision>
            <geometry>
                <sphere radius="0.05"/>
            </geometry>
        </collision>
        <inertial>
            <mass value="0.3"/>
            <origin xyz="0 0 0"/>
            <inertia
                ixx="0.0003"
                ixy="0"
                ixz="0"
                iyy="0.0003"
                iyz="0"
                izz="0.0003"/>
        </inertial>
    </link>

    <joint name="caster_left_joint" type="fixed">
        <parent link="base_link"/>
        <child link="caster_wheel_left"/>
        <origin xyz="-0.20 0.10 0.06"/>  <!-- rear, spread left -->
    </joint>

    <!-- ============================= -->
    <!-- Rear Caster Right             -->
    <!-- ============================= -->

    <link name="caster_wheel_right">
        <visual>
            <geometry>
                <sphere radius="0.05"/>
            </geometry>
            <material name="grey"/>
        </visual>
        <collision>
            <geometry>
                <sphere radius="0.05"/>
            </geometry>
        </collision>
        <inertial>
            <mass value="0.3"/>
            <origin xyz="0 0 0"/>
            <inertia
                ixx="0.0003"
                ixy="0"
                ixz="0"
                iyy="0.0003"
                iyz="0"
                izz="0.0003"/>
        </inertial>
    </link>

    <joint name="caster_right_joint" type="fixed">
        <parent link="base_link"/>
        <child link="caster_wheel_right"/>
        <origin xyz="-0.20 -0.10 0.06"/>  <!-- rear, spread right -->
    </joint>


    <!-- Front Caster Left -->
    <link name="caster_front_left">
        <visual>
            <geometry><sphere radius="0.05"/></geometry>
            <material name="grey"/>
        </visual>
        <collision>
            <geometry><sphere radius="0.05"/></geometry>
        </collision>
        <inertial>
            <mass value="0.3"/>
            <origin xyz="0 0 0"/>
            <inertia ixx="0.0003" ixy="0" ixz="0"
                    iyy="0.0003" iyz="0" izz="0.0003"/>
        </inertial>
    </link>

    <joint name="caster_front_left_joint" type="fixed">
        <parent link="base_link"/>
        <child link="caster_front_left"/>
        <origin xyz="0.17 0.10 0.06"/>
    </joint>

    <!-- Front Caster Right -->
    <link name="caster_front_right">
        <visual>
            <geometry><sphere radius="0.05"/></geometry>
            <material name="grey"/>
        </visual>
        <collision>
            <geometry><sphere radius="0.05"/></geometry>
        </collision>
        <inertial>
            <mass value="0.3"/>
            <origin xyz="0 0 0"/>
            <inertia ixx="0.0003" ixy="0" ixz="0"
                    iyy="0.0003" iyz="0" izz="0.0003"/>
        </inertial>
    </link>

    <joint name="caster_front_right_joint" type="fixed">
        <parent link="base_link"/>
        <child link="caster_front_right"/>
        <origin xyz="0.17 -0.10 0.06"/>
    </joint>

</robot>